2023-05-30 16:10:44,369 ERROR D:\Django\SF\venv\Lib\site-packages\django\utils\log.py Internal Server Error: /news/ (<class 'django.core.exceptions.ImproperlyConfigured'>, ImproperlyConfigured('settings.DATABASES is improperly configured. Please supply the NAME value.'), <traceback object at 0x00000280FD4339C0>)
Traceback (most recent call last):
  File "D:\Django\SF\venv\Lib\site-packages\django\core\handlers\exception.py", line 55, in inner
    response = get_response(request)
               ^^^^^^^^^^^^^^^^^^^^^
  File "D:\Django\SF\venv\Lib\site-packages\django\core\handlers\base.py", line 197, in _get_response
    response = wrapped_callback(request, *callback_args, **callback_kwargs)
               ^^^^^^^^^^^^^^^^^^^^^^^^^^^^^^^^^^^^^^^^^^^^^^^^^^^^^^^^^^^^
  File "D:\Django\SF\venv\Lib\site-packages\django\views\generic\base.py", line 104, in view
    return self.dispatch(request, *args, **kwargs)
           ^^^^^^^^^^^^^^^^^^^^^^^^^^^^^^^^^^^^^^^
  File "D:\Django\SF\venv\Lib\site-packages\django\views\generic\base.py", line 143, in dispatch
    return handler(request, *args, **kwargs)
           ^^^^^^^^^^^^^^^^^^^^^^^^^^^^^^^^^
  File "D:\Django\SF\venv\Lib\site-packages\django\views\generic\list.py", line 174, in get
    context = self.get_context_data()
              ^^^^^^^^^^^^^^^^^^^^^^^
  File "D:\Django\SF\venv\Lib\site-packages\django\views\generic\list.py", line 128, in get_context_data
    paginator, page, queryset, is_paginated = self.paginate_queryset(
                                              ^^^^^^^^^^^^^^^^^^^^^^^
  File "D:\Django\SF\venv\Lib\site-packages\django\views\generic\list.py", line 73, in paginate_queryset
    page = paginator.page(page_number)
           ^^^^^^^^^^^^^^^^^^^^^^^^^^^
  File "D:\Django\SF\venv\Lib\site-packages\django\core\paginator.py", line 72, in page
    number = self.validate_number(number)
             ^^^^^^^^^^^^^^^^^^^^^^^^^^^^
  File "D:\Django\SF\venv\Lib\site-packages\django\core\paginator.py", line 53, in validate_number
    if number > self.num_pages:
                ^^^^^^^^^^^^^^
  File "D:\Django\SF\venv\Lib\site-packages\django\utils\functional.py", line 57, in __get__
    res = instance.__dict__[self.name] = self.func(instance)
                                         ^^^^^^^^^^^^^^^^^^^
  File "D:\Django\SF\venv\Lib\site-packages\django\core\paginator.py", line 99, in num_pages
    if self.count == 0 and not self.allow_empty_first_page:
       ^^^^^^^^^^
  File "D:\Django\SF\venv\Lib\site-packages\django\utils\functional.py", line 57, in __get__
    res = instance.__dict__[self.name] = self.func(instance)
                                         ^^^^^^^^^^^^^^^^^^^
  File "D:\Django\SF\venv\Lib\site-packages\django\core\paginator.py", line 93, in count
    return c()
           ^^^
  File "D:\Django\SF\venv\Lib\site-packages\django\db\models\query.py", line 608, in count
    return self.query.get_count(using=self.db)
           ^^^^^^^^^^^^^^^^^^^^^^^^^^^^^^^^^^^
  File "D:\Django\SF\venv\Lib\site-packages\django\db\models\sql\query.py", line 536, in get_count
    return obj.get_aggregation(using, {"__count": Count("*")})["__count"]
           ^^^^^^^^^^^^^^^^^^^^^^^^^^^^^^^^^^^^^^^^^^^^^^^^^^^
  File "D:\Django\SF\venv\Lib\site-packages\django\db\models\sql\query.py", line 522, in get_aggregation
    result = compiler.execute_sql(SINGLE)
             ^^^^^^^^^^^^^^^^^^^^^^^^^^^^
  File "D:\Django\SF\venv\Lib\site-packages\django\db\models\sql\compiler.py", line 1558, in execute_sql
    cursor = self.connection.cursor()
             ^^^^^^^^^^^^^^^^^^^^^^^^
  File "D:\Django\SF\venv\Lib\site-packages\django\utils\asyncio.py", line 26, in inner
    return func(*args, **kwargs)
           ^^^^^^^^^^^^^^^^^^^^^
  File "D:\Django\SF\venv\Lib\site-packages\django\db\backends\base\base.py", line 330, in cursor
    return self._cursor()
           ^^^^^^^^^^^^^^
  File "D:\Django\SF\venv\Lib\site-packages\django\db\backends\base\base.py", line 306, in _cursor
    self.ensure_connection()
  File "D:\Django\SF\venv\Lib\site-packages\django\utils\asyncio.py", line 26, in inner
    return func(*args, **kwargs)
           ^^^^^^^^^^^^^^^^^^^^^
  File "D:\Django\SF\venv\Lib\site-packages\django\db\backends\base\base.py", line 289, in ensure_connection
    self.connect()
  File "D:\Django\SF\venv\Lib\site-packages\django\utils\asyncio.py", line 26, in inner
    return func(*args, **kwargs)
           ^^^^^^^^^^^^^^^^^^^^^
  File "D:\Django\SF\venv\Lib\site-packages\django\db\backends\base\base.py", line 269, in connect
    conn_params = self.get_connection_params()
                  ^^^^^^^^^^^^^^^^^^^^^^^^^^^^
  File "D:\Django\SF\venv\Lib\site-packages\django\db\backends\sqlite3\base.py", line 149, in get_connection_params
    raise ImproperlyConfigured(
django.core.exceptions.ImproperlyConfigured: settings.DATABASES is improperly configured. Please supply the NAME value.
2023-05-30 16:10:44,430 ERROR D:\Django\SF\venv\Lib\site-packages\django\core\servers\basehttp.py "GET /news/ HTTP/1.1" 500 145 None
